Workbook

Sheet Registro_Actividades
A1: ID_Actividad | B1: Folio | C1: Fecha_Captura | D1: Clave_Proceso | E1: Clave_Proceso_Txt | F1: Meta | G1: Nombre_Meta | H1: Area | I1: Direccion | J1: Unidad_Medida | K1: Meta_Anual | L1: Enfoque_Actividad | M1: Nombre_Actividad | N1: Descripcion_Breve | O1: Temporalidad | P1: Fecha_Inicio | Q1: Fecha_Fin | R1: Total_Sesiones | S1: Disciplina | T1: Subdisciplina | U1: Tipo_Actividad | V1: Proceso_Institucional | W1: Formato | X1: Tipo_Espacio | Y1: Nombre_Espacio | Z1: Especifique_Espacio | AA1: Foto_Evidencia | AB1: Genera_Ingresos | AC1: Monto_Ingreso | AD1: Agentes_Con_Contrato | AE1: Cantidad_Agentes | AF1: Registros_INDAUTOR | AG1: Folio_INDAUTOR | AH1: Costo | AI1: Costo_Minimo | AJ1: Costo_Maximo | AK1: Detalle_Tarifas | AL1: Usuario_Registra | AM1: Promesa_NC | AN1: Eje_PG | AO1: Objetivo_PG | AP1: Estrategia_PG | AQ1: Acciones_PG | AR1: Eje_Tranversal_PEC | AS1: Enfoque_Accion | AT1: Linea_PEC | AU1: Estrategia_PEC | AV1: Acciones_PEC | AW1: Metas_PEC | AX1: Actividad | AY1: Categoria_Helper | AZ1: Tipo_Proceso_Formacion | BA1: Tipo_Oferta_Formacion | BB1: Tipo_Agente_Apoyado | BC1: Cantidad_Agente_Apoyado | BD1: Condicion_Agente | BE1: Nombre_Agente | BF1: Con_Apoyo | BG1: Tipo_Apoyo | BH1: Monto_Total_Contratado | BI1: Tipo_Proyecto_Artistico | BJ1: Tipo_Circulacion | BK1: Tipo_Patrimonio | BL1: Tipo_Convenio | BM1: Vinculacion_Actores | BN1: Tipo_Vinculacion | BO1: Detalle_Calendario | BP1: Ubicacion_GPS | BQ1: Estado_Actividad | BR1: Indicador_Oficial | BS1: Nombre_Indicador | BT1: Instrumento
A2: ACT00031 | B2: SC-260604-111329 | C2: 46177.468 | D2: 94 | E2: PB3572 | F2: Gestión de programas de exposiciones, actividades formativas y académicas en los Museos de la Secretaría de Cultura y actividades extramuros | G2: Creación de actividades para poblaciones especificas como mujeres, niños y niñas, adultos mayores y discapacidad en los Museos adscritos a la Secretaria de Cultura | H2: SUBSECRETARÍA DE DESARROLLO Y PROMOCIÓN ARTÍSTICA Y CULTURAL | I2: DIRECCIÓN GENERAL DE MUSEOS, ARTES VISUALES Y EXPOSICIONES | J2: Número de Actividades realizadas | K2: 12 | L2: Cultural | M2: Juguetes tipicos en estampa alternativa | N2: Fomento del sentido crítico sobre la importancia de las artes visuales en el desarrollo cognitivo, social, humano y artístico. | O2: Única | P2: 46120 | Q2: 46120 | R2: 1 | S2: Cultura comunitaria | T2: Procesos de memoria | U2: Taller | V2: Ninguna | W2: Presencial | X2: Espacio Público | Z2: Centro Nuevo Comienzo Balcones de las Joyas | AB2: FALSE | AD2: FALSE | AF2: FALSE | AH2: Sin costo | AL2: ccardonav@guanajuato.gob.mx | AM2: Arraigo y empoderamiento cultural de comunidades. | AN2: 2 Igualdad | AO2: 2.2 Fortalecer cohesión social | AP2: 2.2 Fortalecer cohesión social | AQ2: 2.2.3.2 Promover la participación de grupos prioritarios en actividades culturales | AR2: Inclusión | AS2: Ninguno (Población General) | AT2: Fortalecimiento de la participación ciudadana y la mediación cultural | AU2: Impulso a la ampliación de la oferta cultural en los territorios. | AV2: Fortalecer la programación cultural en espacios públicos, espacios alternativos y otros espacios culturales. | AW2: Incrementar en 25% la oferta cultural realizada en los municipios. | AX2: Taller | AY2: Mediación | BC2: 0 | BF2: TRUE | BG2: Especie | BL2: Convenio de colaboración entre la DGMAE y la Secretaría del Nuevo Comienzo | BM2: Sí | BN2: Acompañamiento Técnico | BP2: Abierta | BR2: =VLOOKUP(BQ2, Cat_Indicadores!B:C, 2, FALSE) -> #N/A
A3: ACT00032 | B3: SC-260604-160740 | C3: 46177.672 | D3: 94 | E3: PB3572 | F3: Gestión de programas de exposiciones, actividades formativas y académicas en los Museos de la Secretaría de Cultura y actividades extramuros | G3: Creación de actividades para poblaciones especificas como mujeres, niños y niñas, adultos mayores y discapacidad en los Museos adscritos a la Secretaria de Cultura | H3: SUBSECRETARÍA DE DESARROLLO Y PROMOCIÓN ARTÍSTICA Y CULTURAL | I3: DIRECCIÓN GENERAL DE MUSEOS, ARTES VISUALES Y EXPOSICIONES | J3: Número de Actividades realizadas | K3: 12 | L3: Cultural | M3: Juguetes tipicos en estampa alternativa | N3: Fomento del sentido crítico sobre la importancia de las artes visuales en el desarrollo cognitivo, social, humano y artístico. | O3: Única | P3: 46129 | Q3: 46129 | R3: 1 | S3: Cultura comunitaria | T3: Procesos de memoria | U3: Taller | V3: Ninguna | W3: Presencial | X3: Espacio Público | Z3: Centro Nuevo Comienzo Nuevo Amanecer | AB3: FALSE | AD3: FALSE | AF3: FALSE | AH3: Sin costo | AL3: ccardonav@guanajuato.gob.mx | AM3: Arraigo y empoderamiento cultural de comunidades. | AN3: 2 Igualdad | AO3: 2.2 Fortalecer cohesión social | AP3: 2.2 Fortalecer cohesión social | AQ3: 2.2.3.2 Promover la participación de grupos prioritarios en actividades culturales | AR3: Inclusión | AS3: NNA (Niñas, Niños y Adolescentes) | AT3: Fortalecimiento de la participación ciudadana y la mediación cultural | AU3: Impulso a la ampliación de la oferta cultural en los territorios. | AV3: Fortalecer la programación cultural en espacios públicos, espacios alternativos y otros espacios culturales. | AW3: Incrementar en 25% la oferta cultural realizada en los municipios. | AX3: Taller | AY3: Mediación | BC3: 0 | BF3: TRUE | BG3: Especie | BL3: Convenio de colaboración entre la DGMAVE y la Secretaría del Nuevo Comienzo | BM3: Sí | BN3: Acompañamiento Técnico | BP3: Abierta | BR3: =VLOOKUP(BQ3, Cat_Indicadores!B:C, 2, FALSE) -> #N/A
A4: ACT00033 | B4: SC-260605-100441 | C4: 46178.42 | D4: 94 | E4: PB3572 | F4: Gestión de programas de exposiciones, actividades formativas y académicas en los Museos de la Secretaría de Cultura y actividades extramuros | G4: Creación de actividades para poblaciones especificas como mujeres, niños y niñas, adultos mayores y discapacidad en los Museos adscritos a la Secretaria de Cultura | H4: SUBSECRETARÍA DE DESARROLLO Y PROMOCIÓN ARTÍSTICA Y CULTURAL | I4: DIRECCIÓN GENERAL DE MUSEOS, ARTES VISUALES Y EXPOSICIONES | J4: Número de Actividades realizadas | K4: 12 | L4: Cultural | M4: Derechos de los niños y niñas | N4: Fomento del sentido crítico sobre la importancia de las artes visuales en el desarrollo cognitivo, social, humano y artístico. | O4: Única | P4: 46127 | Q4: 46127 | R4: 1 | S4: Cultura comunitaria | T4: Mediación cultural | U4: Taller | V4: Ninguna | W4: Presencial | X4: Espacio Público | Z4: Escuela Primaria Vespertina “Francisco Javier Mina” | AB4: FALSE | AD4: FALSE | AF4: FALSE | AH4: Sin costo | AL4: ccardonav@guanajuato.gob.mx | AM4: Arraigo y empoderamiento cultural de comunidades. | AN4: 2 Igualdad | AO4: 2.2 Fortalecer cohesión social | AP4: 2.2 Fortalecer cohesión social | AQ4: 2.2.3.2 Promover la participación de grupos prioritarios en actividades culturales | AR4: Inclusión | AS4: NNA (Niñas, Niños y Adolescentes) | AT4: Fortalecimiento de la participación ciudadana y la mediación cultural | AU4: Impulso a la ampliación de la oferta cultural en los territorios. | AV4: Fortalecer la programación cultural en espacios públicos, espacios alternativos y otros espacios culturales. | AW4: Incrementar en 25% la oferta cultural realizada en los municipios. | AX4: Taller | AY4: Mediación | BC4: 0 | BF4: TRUE | BG4: Especie | BH4: 0 | BL4: Convenio de colaboración entre la DGMAVE y la Secretaría del Nuevo Comienzo | BM4: Sí | BN4: Acompañamiento Técnico | BP4: Abierta | BR4: =VLOOKUP(BQ4, Cat_Indicadores!B:C, 2, FALSE) -> #N/A
A5: ACT00034 | B5: SC-260605-103419 | C5: 46178.44 | D5: 94 | E5: PB3572 | F5: Gestión de programas de exposiciones, actividades formativas y académicas en los Museos de la Secretaría de Cultura y actividades extramuros | G5: Creación de actividades para poblaciones especificas como mujeres, niños y niñas, adultos mayores y discapacidad en los Museos adscritos a la Secretaria de Cultura | H5: SUBSECRETARÍA DE DESARROLLO Y PROMOCIÓN ARTÍSTICA Y CULTURAL | I5: DIRECCIÓN GENERAL DE MUSEOS, ARTES VISUALES Y EXPOSICIONES | J5: Número de Actividades realizadas | K5: 12 | L5: Cultural | M5: Acoso Escolar | N5: Incentivar y fomentar un sentido crítico sobre la importancia de los derechos de los niños, niñas y adolescentes, en el desarrollo cognitivo, social, humano y artístico en la Escuela Primaria Vespertina Francisco Javier Mina, a través del programa “El Museo a la vuelta de tu casa”. | O5: Única | P5: 46134 | Q5: 46134 | R5: 1 | S5: Cultura comunitaria | T5: Mediación cultural | U5: Taller | V5: Ninguna | W5: Presencial | X5: Espacio Público | Z5: Escuela Primaria Vespertina “Francisco Javier Mina” | AB5: FALSE | AD5: FALSE | AF5: FALSE | AH5: Sin costo | AL5: ccardonav@guanajuato.gob.mx | AM5: Arraigo y empoderamiento cultural de comunidades. | AN5: 2 Igualdad | AO5: 2.2 Fortalecer cohesión social | AP5: 2.2 Fortalecer cohesión social | AQ5: 2.2.3.2 Promover la participación de grupos prioritarios en actividades culturales | AR5: Inclusión | AS5: NNA (Niñas, Niños y Adolescentes) | AT5: Fortalecimiento de la participación ciudadana y la mediación cultural | AU5: Impulso a la ampliación de la oferta cultural en los territorios. | AV5: Fortalecer la programación cultural en espacios públicos, espacios alternativos y otros espacios culturales. | AW5: Incrementar en 25% la oferta cultural realizada en los municipios. | AX5: Taller | AY5: Mediación | BC5: 0 | BF5: TRUE | BG5: Especie | BL5: Convenio de colaboración entre la DGMAVE y la Secretaría del Nuevo Comienzo | BM5: Sí | BN5: Acompañamiento Técnico | BP5: Abierta | BR5: =VLOOKUP(BQ5, Cat_Indicadores!B:C, 2, FALSE) -> #N/A
A6: ACT00035 | B6: SC-260605-110629 | C6: 46178.463 | D6: 94 | E6: PB3572 | F6: Gestión de programas de exposiciones, actividades formativas y académicas en los Museos de la Secretaría de Cultura y actividades extramuros | G6: Creación de actividades para poblaciones especificas como mujeres, niños y niñas, adultos mayores y discapacidad en los Museos adscritos a la Secretaria de Cultura | H6: SUBSECRETARÍA DE DESARROLLO Y PROMOCIÓN ARTÍSTICA Y CULTURAL | I6: DIRECCIÓN GENERAL DE MUSEOS, ARTES VISUALES Y EXPOSICIONES | J6: Número de Actividades realizadas | K6: 12 | L6: Cultural | M6: Sana Convivencia | N6: Incentivar y fomentar un sentido crítico sobre la importancia de los derechos de los niños, niñas y adolescentes, en el desarrollo cognitivo, social, humano y artístico en la Escuela Primaria Vespertina Francisco Javier Mina, a través del programa “El Museo a la vuelta de tu casa”. | O6: Única | P6: 46141 | Q6: 46141 | R6: 1 | S6: Cultura comunitaria | T6: Mediación cultural | U6: Taller | V6: Ninguna | W6: Presencial | X6: Espacio Público | Z6: Escuela Primaria Vespertina “Francisco Javier Mina” | AB6: FALSE | AD6: FALSE | AF6: FALSE | AH6: Sin costo | AL6: ccardonav@guanajuato.gob.mx | AM6: Arraigo y empoderamiento cultural de comunidades. | AN6: 2 Igualdad | AO6: 2.2 Fortalecer cohesión social | AP6: 2.2 Fortalecer cohesión social | AQ6: 2.2.3.2 Promover la participación de grupos prioritarios en actividades culturales | AR6: Inclusión | AS6: NNA (Niñas, Niños y Adolescentes) | AT6: Fortalecimiento de la participación ciudadana y la mediación cultural | AU6: Impulso a la ampliación de la oferta cultural en los territorios. | AV6: Fortalecer la programación cultural en espacios públicos, espacios alternativos y otros espacios culturales. | AW6: Incrementar en 25% la oferta cultural realizada en los municipios. | AX6: Taller | AY6: Mediación | BC6: 0 | BF6: TRUE | BG6: Especie | BH6: 0 | BL6: Convenio de colaboración entre la DGMAVE y la Secretaría del Nuevo Comienzo | BM6: Sí | BN6: Acompañamiento Técnico | BP6: Abierta | BR6: =VLOOKUP(BQ6, Cat_Indicadores!B:C, 2, FALSE) -> #N/A
A7: ACT00036 | B7: SC-260610-105550 | C7: 46183.455 | D7: 94 | E7: PB3572 | F7: Gestión de programas de exposiciones, actividades formativas y académicas en los Museos de la Secretaría de Cultura y actividades extramuros | G7: Creación de actividades para poblaciones especificas como mujeres, niños y niñas, adultos mayores y discapacidad en los Museos adscritos a la Secretaria de Cultura | H7: SUBSECRETARÍA DE DESARROLLO Y PROMOCIÓN ARTÍSTICA Y CULTURAL | I7: DIRECCIÓN GENERAL DE MUSEOS, ARTES VISUALES Y EXPOSICIONES | J7: Número de Actividades realizadas | K7: 12 | L7: Cultural | M7: Tarjeta Española para Mamá | N7: Incentivar y fomentar un sentido crítico sobre la importancia de los derechos de los niños, niñas y adolescentes, en el desarrollo cognitivo, social, humano y artístico en la Escuela Primaria Vespertina Francisco Javier Mina, a través del programa “El Museo a la vuelta de tu casa”. | O7: Única | P7: 46150 | Q7: 46150 | R7: 1 | S7: Cultura comunitaria | T7: Mediación cultural | U7: Taller | V7: Ninguna | W7: Presencial | X7: Espacio Público | Z7: Centro Nuevo Comienzo Nuevo Amanecer | AB7: FALSE | AD7: FALSE | AF7: FALSE | AH7: Sin costo | AL7: ccardonav@guanajuato.gob.mx | AM7: Arraigo y empoderamiento cultural de comunidades. | AN7: 2 Igualdad | AO7: 2.2 Fortalecer cohesión social | AP7: 2.2 Fortalecer cohesión social | AQ7: 2.2.3.2 Promover la participación de grupos prioritarios en actividades culturales | AR7: Inclusión | AS7: NNA (Niñas, Niños y Adolescentes) | AT7: Fortalecimiento de la participación ciudadana y la mediación cultural | AU7: Impulso a la ampliación de la oferta cultural en los territorios. | AV7: Fortalecer la programación cultural en espacios públicos, espacios alternativos y otros espacios culturales. | AW7: Incrementar en 25% la oferta cultural realizada en los municipios. | AX7: Taller | AY7: Mediación | BC7: 0 | BF7: TRUE | BG7: Especie | BL7: Convenio de colaboración entre la DGMAVE y la Secretaría del Nuevo Comienzo | BM7: Sí | BN7: Acompañamiento Técnico | BP7: Abierta | BR7: =VLOOKUP(BQ7, Cat_Indicadores!B:C, 2, FALSE) -> #N/A
A8: ACT00037 | B8: SC-260610-114106 | C8: 46183.487 | D8: 94 | E8: PB3572 | F8: Gestión de programas de exposiciones, actividades formativas y académicas en los Museos de la Secretaría de Cultura y actividades extramuros | G8: Creación de actividades para poblaciones especificas como mujeres, niños y niñas, adultos mayores y discapacidad en los Museos adscritos a la Secretaria de Cultura | H8: SUBSECRETARÍA DE DESARROLLO Y PROMOCIÓN ARTÍSTICA Y CULTURAL | I8: DIRECCIÓN GENERAL DE MUSEOS, ARTES VISUALES Y EXPOSICIONES | J8: Número de Actividades realizadas | K8: 12 | L8: Cultural | M8: Tarjeta Española para Mamá | N8: Incentivar y fomentar un sentido crítico sobre la importancia de los derechos de los niños, niñas y adolescentes, en el desarrollo cognitivo, social, humano y artístico en la Escuela Primaria Vespertina Francisco Javier Mina, a través del programa “El Museo a la vuelta de tu casa”. | O8: Única | P8: 46186 | Q8: 46186 | R8: 1 | S8: Cultura comunitaria | T8: Mediación cultural | U8: Taller | V8: Ninguna | W8: Presencial | X8: Espacio Público | Z8: Centro Nuevo Comienzo Balcones de las Joyas | AB8: FALSE | AD8: FALSE | AF8: FALSE | AH8: Sin costo | AL8: ccardonav@guanajuato.gob.mx | AM8: Arraigo y empoderamiento cultural de comunidades. | AN8: 2 Igualdad | AO8: 2.2 Fortalecer cohesión social | AP8: 2.2 Fortalecer cohesión social | AQ8: 2.2.3.2 Promover la participación de grupos prioritarios en actividades culturales | AR8: Inclusión | AS8: Ninguno (Población General) | AT8: Fortalecimiento de la participación ciudadana y la mediación cultural | AU8: Impulso a la ampliación de la oferta cultural en los territorios. | AV8: Fortalecer la programación cultural en espacios públicos, espacios alternativos y otros espacios culturales. | AW8: Incrementar en 25% la oferta cultural realizada en los municipios. | AX8: Taller | AY8: Mediación | BC8: 0 | BF8: TRUE | BG8: Especie | BL8: Convenio de colaboración entre la DGMAVE y la Secretaría del Nuevo Comienzo | BM8: Sí | BN8: Acompañamiento Técnico | BP8: Abierta | BR8: =VLOOKUP(BQ8, Cat_Indicadores!B:C, 2, FALSE) -> #N/A
A9: ACT00038 | B9: SC-260611-102905 | C9: 46184.437 | D9: 92 | E9: PB3572 | F9: Gestión de programas de exposiciones, actividades formativas y académicas en los Museos de la Secretaría de Cultura y actividades extramuros | G9: Creación y participación en actividades formativas y académicas de los museos adscritos a la Secretaria de Cultura | H9: SUBSECRETARÍA DE DESARROLLO Y PROMOCIÓN ARTÍSTICA Y CULTURAL | I9: DIRECCIÓN GENERAL DE MUSEOS, ARTES VISUALES Y EXPOSICIONES | J9: Número de Actividades realizadas | K9: 800 | L9: Cultural | M9: 1EEM "Diálogos de Museos y política pública" | N9: El I Encuentro Estatal de Museos de Guanajuato es un espacio de reunión y diálogo que convoca a representantes de museos, gestores culturales y profesionales del sector de los 46 municipios del estado, con el propósito de compartir experiencias, reflexionar sobre los retos actuales y visibilizar la diversidad del patrimonio cultural guanajuatense. Este encuentro impulsa la colaboración intermunicipal y el trabajo en red como ejes para fortalecer el papel social, educativo y cultural de los museos. | O9: Única | P9: 46169 | Q9: 46169 | R9: 1 | S9: Cultura comunitaria | T9: Gestión cultural | U9: Encuentro cultural | V9: Evaluación | W9: Presencial | X9: Espacio Privado | Z9: Hotel Hotsson | AB9: FALSE | AD9: TRUE | AE9: 1 | AF9: FALSE | AH9: Sin costo | AL9: ccardonav@guanajuato.gob.mx | AM9: Formación de formadores artísticos y culturales: Cursos y talleres de capacitación artística para docentes. Encuentros entre formadores de casas de cultura. Plataforma de colaboración entre instituciones culturales. | AN9: 2 Igualdad | AO9: 2.4 Reducir brechas de desigualdad | AP9: 2.4.3 Descentralización de la oferta cultural | AQ9: 2.4.3.3 Incidir en el involucramiento de las personas con el ecosistema cultural | AR9: Cooperación | AT9: Fortalecimiento de la participación ciudadana y la mediación cultural | AU9: Fortalecimiento del diálogo, la mediación y las capacidades de las redes comunitarias. | AV9: Fortalecer las capacidades de autoridades locales y estatales | AW9: Incrementar en 25% la oferta cultural realizada en los municipios. | AX9: Asesoría especializada | AY9: Formación | AZ9: Formación | BC9: 0 | BF9: TRUE | BG9: Asesoría | BL9: Contrato de Prestación de Servicios | BM9: Sí | BN9: Acompañamiento Técnico | BP9: Abierta | BR9: =VLOOKUP(BQ9, Cat_Indicadores!B:C, 2, FALSE) -> #N/A
A10: ACT00039 | B10: SC-260611-111846 | C10: 46184.471 | D10: 92 | E10: PB3572 | F10: Gestión de programas de exposiciones, actividades formativas y académicas en los Museos de la Secretaría de Cultura y actividades extramuros | G10: Creación y participación en actividades formativas y académicas de los museos adscritos a la Secretaria de Cultura | H10: SUBSECRETARÍA DE DESARROLLO Y PROMOCIÓN ARTÍSTICA Y CULTURAL | I10: DIRECCIÓN GENERAL DE MUSEOS, ARTES VISUALES Y EXPOSICIONES | J10: Número de Actividades realizadas | K10: 800 | L10: Cultural | M10: 1EEM "Vámonos conociendo" | N10: Sesión de taller a cargo del Laboratorio Creativo Luciérnaga | O10: Única | P10: 46169 | Q10: 46169 | R10: 1 | S10: Cultura comunitaria | T10: Mediación cultural | U10: Taller | V10: Evaluación | W10: Presencial | X10: Espacio Privado | Z10: Hotel Hotsson | AB10: FALSE | AD10: TRUE | AE10: 1 | AF10: FALSE | AH10: Sin costo | AL10: ccardonav@guanajuato.gob.mx | AM10: Formación de formadores artísticos y culturales: Cursos y talleres de capacitación artística para docentes. Encuentros entre formadores de casas de cultura. Plataforma de colaboración entre instituciones culturales. | AN10: 2 Igualdad | AO10: 2.4 Reducir brechas de desigualdad | AP10: 2.4.3 Descentralización de la oferta cultural | AQ10: 2.4.3.3 Incidir en el involucramiento de las personas con el ecosistema cultural | AR10: Cooperación | AT10: Fortalecimiento de la participación ciudadana y la mediación cultural | AU10: Fortalecimiento del diálogo, la mediación y las capacidades de las redes comunitarias. | AV10: Fortalecer las capacidades de autoridades locales y estatales | AW10: Incrementar en 25% la oferta cultural realizada en los municipios. | AX10: Taller | AY10: Mediación | BC10: 0 | BF10: TRUE | BG10: Asesoría | BL10: Contrato de Prestación de Servicios | BM10: Sí | BN10: Acompañamiento Técnico | BP10: Abierta | BR10: =VLOOKUP(BQ10, Cat_Indicadores!B:C, 2, FALSE) -> #N/A
A11: ACT00040 | B11: SC-260611-140443 | C11: 46184.587 | D11: 92 | E11: PB3572 | F11: Gestión de programas de exposiciones, actividades formativas y académicas en los Museos de la Secretaría de Cultura y actividades extramuros | G11: Creación y participación en actividades formativas y académicas de los museos adscritos a la Secretaria de Cultura | H11: SUBSECRETARÍA DE DESARROLLO Y PROMOCIÓN ARTÍSTICA Y CULTURAL | I11: DIRECCIÓN GENERAL DE MUSEOS, ARTES VISUALES Y EXPOSICIONES | J11: Número de Actividades realizadas | K11: 800 | L11: Cultural | M11: 1 EEM "Conferencia comunidades y museos" | N11: En conversación Álvaro Octavio Lara Huerta, Subsecretario deDesarrollo y Promoción Artística y Cultural de Guanajuato | O11: Única | P11: 46170 | Q11: 46170 | R11: 1 | S11: Cultura comunitaria | T11: Gestión cultural | U11: Conferencia | V11: Ninguna | W11: Presencial | X11: Espacio Privado | Z11: Hotel Hotsson | AB11: FALSE | AD11: TRUE | AE11: 1 | AF11: FALSE | AH11: Sin costo | AL11: ccardonav@guanajuato.gob.mx | AM11: Formación de formadores artísticos y culturales: Cursos y talleres de capacitación artística para docentes. Encuentros entre formadores de casas de cultura. Plataforma de colaboración entre instituciones culturales. | AN11: 2 Igualdad | AO11: 2.4 Reducir brechas de desigualdad | AP11: 2.4.3 Descentralización de la oferta cultural | AQ11: 2.4.3.3 Incidir en el involucramiento de las personas con el ecosistema cultural | AR11: Cooperación | AT11: Fortalecimiento de la participación ciudadana y la mediación cultural | AU11: Fortalecimiento del diálogo, la mediación y las capacidades de las redes comunitarias. | AV11: Fortalecer las capacidades de autoridades locales y estatales | AW11: Incrementar en 25% la oferta cultural realizada en los municipios. | AX11: Asesoría especializada | AY11: Formación | BC11: 0 | BF11: TRUE | BG11: Asesoría | BL11: Contrato de Prestacion de Servicios | BM11: Sí | BN11: Acompañamiento Técnico | BP11: Abierta | BR11: =VLOOKUP(BQ11, Cat_Indicadores!B:C, 2, FALSE) -> #N/A
A12: ACT00041 | B12: SC-260611-143318 | C12: 46184.606 | D12: 92 | E12: PB3572 | F12: Gestión de programas de exposiciones, actividades formativas y académicas en los Museos de la Secretaría de Cultura y actividades extramuros | G12: Creación y participación en actividades formativas y académicas de los museos adscritos a la Secretaria de Cultura | H12: SUBSECRETARÍA DE DESARROLLO Y PROMOCIÓN ARTÍSTICA Y CULTURAL | I12: DIRECCIÓN GENERAL DE MUSEOS, ARTES VISUALES Y EXPOSICIONES | J12: Número de Actividades realizadas | K12: 800 | L12: Cultural | M12: 1 EEM "Conociendo los museos de Guanajuato. Sesion de PechaKucha" | N12: Presentación de los museos con la dinámica PechaKucha. | O12: Única | P12: 46170 | Q12: 46170 | R12: 1 | S12: Cultura comunitaria | T12: Gestión cultural | U12: Vinculación | V12: Ninguna | W12: Presencial | X12: Espacio Privado | Z12: Hotel Hotsson | AB12: FALSE | AD12: FALSE | AF12: FALSE | AH12: Sin costo | AL12: ccardonav@guanajuato.gob.mx | AM12: Formación de formadores artísticos y culturales: Cursos y talleres de capacitación artística para docentes. Encuentros entre formadores de casas de cultura. Plataforma de colaboración entre instituciones culturales. | AN12: 2 Igualdad | AO12: 2.4 Reducir brechas de desigualdad | AP12: 2.4.3 Descentralización de la oferta cultural | AQ12: 2.4.3.3 Incidir en el involucramiento de las personas con el ecosistema cultural | AR12: Inclusión | AT12: Fortalecimiento de la participación ciudadana y la mediación cultural | AU12: Fortalecimiento del diálogo, la mediación y las capacidades de las redes comunitarias. | AV12: Fortalecer las capacidades de autoridades locales y estatales | AW12: Incrementar en 25% la oferta cultural realizada en los municipios. | AX12: Encuentro cultural | AY12: Circulación / Exhibición | BC12: 0 | BF12: TRUE | BG12: Asesoría | BM12: No | BN12: Acompañamiento Técnico | BP12: Abierta | BR12: =VLOOKUP(BQ12, Cat_Indicadores!B:C, 2, FALSE) -> #N/A
A13: ACT00042 | B13: SC-260611-154851 | C13: 46184.659 | D13: 92 | E13: PB3572 | F13: Gestión de programas de exposiciones, actividades formativas y académicas en los Museos de la Secretaría de Cultura y actividades extramuros | G13: Creación y participación en actividades formativas y académicas de los museos adscritos a la Secretaria de Cultura | H13: SUBSECRETARÍA DE DESARROLLO Y PROMOCIÓN ARTÍSTICA Y CULTURAL | I13: DIRECCIÓN GENERAL DE MUSEOS, ARTES VISUALES Y EXPOSICIONES | J13: Número de Actividades realizadas | K13: 800 | L13: Cultural | M13: 1 EEM " Conferencia el diseño de exhibiciones" | N13: La conferencia se centró en la importancia de mirar a los públicos. Imparte Gabriel Horner en conversación con Óscar Ascencio. | O13: Única | P13: 46170 | Q13: 46170 | R13: 1 | S13: Cultura comunitaria | T13: Gestión cultural | U13: Conferencia | V13: Ninguna | W13: Presencial | X13: Espacio Privado | Z13: Hotel Hotsson | AB13: FALSE | AD13: TRUE | AE13: 1 | AF13: FALSE | AH13: Sin costo | AL13: ccardonav@guanajuato.gob.mx | AM13: Formación de formadores artísticos y culturales: Cursos y talleres de capacitación artística para docentes. Encuentros entre formadores de casas de cultura. Plataforma de colaboración entre instituciones culturales. | AN13: 2 Igualdad | AO13: 2.4 Reducir brechas de desigualdad | AP13: 2.4.3 Descentralización de la oferta cultural | AQ13: 2.4.3.3 Incidir en el involucramiento de las personas con el ecosistema cultural | AR13: Cooperación | AT13: Fortalecimiento de la participación ciudadana y la mediación cultural | AU13: Fortalecimiento del diálogo, la mediación y las capacidades de las redes comunitarias. | AV13: Fortalecer las capacidades de autoridades locales y estatales | AW13: Incrementar en 25% la oferta cultural realizada en los municipios. | AX13: Asesoría especializada | AY13: Mediación | BC13: 0 | BF13: TRUE | BG13: Asesoría | BL13: Contrato de Prestacion de Servicios | BM13: Sí | BP13: Abierta | BR13: =VLOOKUP(BQ13, Cat_Indicadores!B:C, 2, FALSE) -> #N/A
A14: ACT00043 | B14: SC-260612-103524 | C14: 46185.441 | D14: 92 | E14: PB3572 | F14: Gestión de programas de exposiciones, actividades formativas y académicas en los Museos de la Secretaría de Cultura y actividades extramuros | G14: Creación y participación en actividades formativas y académicas de los museos adscritos a la Secretaria de Cultura | H14: SUBSECRETARÍA DE DESARROLLO Y PROMOCIÓN ARTÍSTICA Y CULTURAL | I14: DIRECCIÓN GENERAL DE MUSEOS, ARTES VISUALES Y EXPOSICIONES | J14: Número de Actividades realizadas | K14: 800 | L14: Cultural | M14: 1 EEM " ¿Qué somos Y qué tenemos en común? | N14: Sesión de taller a cargo del Laboratorio Creativo Luciérnaga | O14: Única | P14: 46170 | Q14: 46170 | R14: 1 | S14: Cultura comunitaria | T14: Mediación cultural | U14: Taller | V14: Evaluación | W14: Presencial | X14: Espacio Privado | Z14: Hotel Hotsson | AB14: FALSE | AD14: TRUE | AE14: 1 | AF14: FALSE | AH14: Sin costo | AL14: ccardonav@guanajuato.gob.mx | AM14: Formación de formadores artísticos y culturales: Cursos y talleres de capacitación artística para docentes. Encuentros entre formadores de casas de cultura. Plataforma de colaboración entre instituciones culturales. | AN14: 2 Igualdad | AO14: 2.4 Reducir brechas de desigualdad | AP14: 2.4.3 Descentralización de la oferta cultural | AQ14: 2.4.3.3 Incidir en el involucramiento de las personas con el ecosistema cultural | AR14: Cooperación | AT14: Fortalecimiento de la participación ciudadana y la mediación cultural | AU14: Fortalecimiento del diálogo, la mediación y las capacidades de las redes comunitarias. | AV14: Fortalecer las capacidades de autoridades locales y estatales | AW14: Incrementar en 25% la oferta cultural realizada en los municipios. | AX14: Taller | AY14: Mediación | BC14: 0 | BF14: TRUE | BG14: Asesoría | BH14: 23200 | BL14: Contrato de Prestación de Servicios | BM14: Sí | BN14: Acompañamiento Técnico | BP14: Abierta | BR14: =VLOOKUP(BQ14, Cat_Indicadores!B:C, 2, FALSE) -> #N/A
A15: ACT00044 | B15: SC-260612-110853 | C15: 46185.465 | D15: 92 | E15: PB3572 | F15: Gestión de programas de exposiciones, actividades formativas y académicas en los Museos de la Secretaría de Cultura y actividades extramuros | G15: Creación y participación en actividades formativas y académicas de los museos adscritos a la Secretaria de Cultura | H15: SUBSECRETARÍA DE DESARROLLO Y PROMOCIÓN ARTÍSTICA Y CULTURAL | I15: DIRECCIÓN GENERAL DE MUSEOS, ARTES VISUALES Y EXPOSICIONES | J15: Número de Actividades realizadas | K15: 800 | L15: Cultural | M15: 1 EEM " Conferencia Las redes sociales, un campo abierto a la comunicación e los emprendimientos culturales" | N15: La conferencia la impartió Melania Chavarría. | O15: Única | P15: 46171 | Q15: 46171 | R15: 1 | S15: Cultura comunitaria | T15: Gestión cultural | U15: Conferencia | V15: Ninguna | W15: Presencial | X15: Espacio Privado | Z15: Hotel Hotsson | AB15: FALSE | AD15: FALSE | AF15: FALSE | AH15: Sin costo | AL15: ccardonav@guanajuato.gob.mx | AM15: Formación de formadores artísticos y culturales: Cursos y talleres de capacitación artística para docentes. Encuentros entre formadores de casas de cultura. Plataforma de colaboración entre instituciones culturales. | AN15: 2 Igualdad | AO15: 2.4 Reducir brechas de desigualdad | AP15: 2.4.3 Descentralización de la oferta cultural | AQ15: 2.4.3.3 Incidir en el involucramiento de las personas con el ecosistema cultural | AR15: Cooperación | AT15: Fortalecimiento de la participación ciudadana y la mediación cultural | AU15: Fortalecimiento del diálogo, la mediación y las capacidades de las redes comunitarias. | AV15: Fortalecer las capacidades de autoridades locales y estatales | AW15: Incrementar en 25% la oferta cultural realizada en los municipios. | AX15: Asesoría especializada | AY15: Formación | AZ15: Formación | BC15: 0 | BF15: TRUE | BG15: Asesoría | BM15: No | BP15: Abierta | BR15: =VLOOKUP(BQ15, Cat_Indicadores!B:C, 2, FALSE) -> #N/A
A16: ACT00045 | B16: SC-260612-113026 | C16: 46185.479 | D16: 92 | E16: PB3572 | F16: Gestión de programas de exposiciones, actividades formativas y académicas en los Museos de la Secretaría de Cultura y actividades extramuros | G16: Creación y participación en actividades formativas y académicas de los museos adscritos a la Secretaria de Cultura | H16: SUBSECRETARÍA DE DESARROLLO Y PROMOCIÓN ARTÍSTICA Y CULTURAL | I16: DIRECCIÓN GENERAL DE MUSEOS, ARTES VISUALES Y EXPOSICIONES | J16: Número de Actividades realizadas | K16: 800 | L16: Cultural | M16: 1 EEM " Conversatorio los retos de la comunicación y la mediación de los museos" | N16: Participan Brenda Galvan, Museo de las identidades leonesas/ICL, Rafael Soldara, Museo de Celaya de Historia Regional, Míriam de los Ángeles | O16: Única | P16: 46171 | Q16: 46171 | R16: 1 | S16: Cultura comunitaria | T16: Mediación cultural | U16: Conversatorio | V16: Ninguna | W16: Presencial | X16: Espacio Privado | Z16: Hotel Hotsson | AB16: FALSE | AD16: FALSE | AF16: FALSE | AH16: Sin costo | AL16: ccardonav@guanajuato.gob.mx | AM16: Formación de formadores artísticos y culturales: Cursos y talleres de capacitación artística para docentes. Encuentros entre formadores de casas de cultura. Plataforma de colaboración entre instituciones culturales. | AN16: 2 Igualdad | AO16: 2.4 Reducir brechas de desigualdad | AP16: 2.4.3 Descentralización de la oferta cultural | AQ16: 2.4.3.3 Incidir en el involucramiento de las personas con el ecosistema cultural | AR16: Inclusión | AS16: Ninguno (Población General) | AT16: Fortalecimiento de la participación ciudadana y la mediación cultural | AU16: Fortalecimiento del diálogo, la mediación y las capacidades de las redes comunitarias. | AV16: Fortalecer las capacidades de autoridades locales y estatales | AW16: Incrementar en 25% la oferta cultural realizada en los municipios. | AX16: Asesoría especializada | AY16: Mediación | BC16: 5 | BD16: Nuevo | BF16: TRUE | BG16: Asesoría | BM16: No | BP16: Abierta | BR16: =VLOOKUP(BQ16, Cat_Indicadores!B:C, 2, FALSE) -> #N/A
A17: ACT00046 | B17: SC-260612-122622 | C17: 46185.518 | D17: 92 | E17: PB3572 | F17: Gestión de programas de exposiciones, actividades formativas y académicas en los Museos de la Secretaría de Cultura y actividades extramuros | G17: Creación y participación en actividades formativas y académicas de los museos adscritos a la Secretaria de Cultura | H17: SUBSECRETARÍA DE DESARROLLO Y PROMOCIÓN ARTÍSTICA Y CULTURAL | I17: DIRECCIÓN GENERAL DE MUSEOS, ARTES VISUALES Y EXPOSICIONES | J17: Número de Actividades realizadas | K17: 800 | L17: Cultural | M17: 1 EEM "Conferencia reflexiones sobre la educación en museos" | N17: Conferencia Impartida por la Mtr. Ariadna Vargas Trejo | O17: Única | P17: 46171 | Q17: 46171 | R17: 1 | S17: Cultura comunitaria | T17: Gestión cultural | U17: Conferencia | V17: Ninguna | W17: Presencial | X17: Espacio Privado | Z17: Hotel Hotsson | AB17: FALSE | AD17: TRUE | AE17: 1 | AF17: FALSE | AH17: Sin costo | AL17: ccardonav@guanajuato.gob.mx | AM17: Formación de formadores artísticos y culturales: Cursos y talleres de capacitación artística para docentes. Encuentros entre formadores de casas de cultura. Plataforma de colaboración entre instituciones culturales. | AN17: 2 Igualdad | AO17: 2.4 Reducir brechas de desigualdad | AP17: 2.4.3 Descentralización de la oferta cultural | AQ17: 2.4.3.3 Incidir en el involucramiento de las personas con el ecosistema cultural | AR17: Cooperación | AT17: Fortalecimiento de la participación ciudadana y la mediación cultural | AU17: Fortalecimiento del diálogo, la mediación y las capacidades de las redes comunitarias. | AV17: Fortalecer las capacidades de autoridades locales y estatales | AW17: Incrementar en 25% la oferta cultural realizada en los municipios. | AX17: Asesoría especializada | AY17: Formación | AZ17: Formación | BC17: 0 | BF17: TRUE | BG17: Asesoría | BH17: 7656.25 | BL17: Contrato de Prestacion de Servicios | BM17: Sí | BN17: Acompañamiento Técnico | BP17: Abierta | BR17: =VLOOKUP(BQ17, Cat_Indicadores!B:C, 2, FALSE) -> #N/A
A18: ACT00017 | B18: SC-260615-100445 | C18: 46188.42 | D18: 92 | E18: PB3572 | F18: Gestión de programas de exposiciones, actividades formativas y académicas en los Museos de la Secretaría de Cultura y actividades extramuros | G18: Creación y participación en actividades formativas y académicas de los museos adscritos a la Secretaria de Cultura | H18: SUBSECRETARÍA DE DESARROLLO Y PROMOCIÓN ARTÍSTICA Y CULTURAL | I18: DIRECCIÓN GENERAL DE MUSEOS, ARTES VISUALES Y EXPOSICIONES | J18: Número de Actividades realizadas | K18: 800 | L18: Cultural | M18: "Museos para la niñez: Torneo de Rubik " | N18: La Asociación Mundial del Cubo (WCA) te invita a participar o presenciar el Torneo de Rubik. Una competencia en la que chicos y grandes pueden demostrar sus habilidades con este popular juego que ha dado la vuelta por todo el mundo. | O18: Única | P18: 46124 | Q18: 46124 | R18: 1 | S18: Multidisciplinario | T18: Interdisciplinario | U18: Activación cultural comunitaria | V18: Ninguna | W18: Presencial | X18: Espacio a Cargo de la Secretaría | Y18: 8 | AB18: FALSE | AD18: FALSE | AF18: FALSE | AH18: Sin costo | AL18: ccardonav@guanajuato.gob.mx | AM18: Juventudes: Apropiación de espacios públicos: revitalizar espacios subutilizados para actividades comunitarias y culturales, con jóvenes en su diseño y gestión. | AN18: 1 Tranquilidad | AO18: 1.2 Fortalecer prevención del delito | AP18: 1.2.2 Fortalecimiento del tejido social | AQ18: 1.2.3.4 Promover una cultura de paz desde las expresiones artísticas y culturales | AR18: Cooperación | AT18: Protección y dinamización del patrimonio, la memoria y los espacios culturales | AU18: Consolidación de los mecanismos de gobernanza para el uso de los espacios cultuales y zonas patrimoniales. | AV18: Promover mecanismos de gobernanza para el aprovechamiento de espacios patrimoniales del estado de Guanajuato (ferias, festivales, encuentros comunitarios, etc.). | AW18: Incrementar un 30% la participación de grupos, colectivos y comunidades en procesos de memoria, investigación, divulgación y difusión del patrimonio material e inmaterial | AX18: Programación cultural en espacio público | AY18: Formación | BC18: 0 | BF18: FALSE | BL18: N/A | BM18: Sí | BP18: Abierta | BR18: =VLOOKUP(BQ18, Cat_Indicadores!B:C, 2, FALSE) -> #N/A
A19: ACT00018 | B19: SC-260615-103418 | C19: 46188.44 | D19: 92 | E19: PB3572 | F19: Gestión de programas de exposiciones, actividades formativas y académicas en los Museos de la Secretaría de Cultura y actividades extramuros | G19: Creación y participación en actividades formativas y académicas de los museos adscritos a la Secretaria de Cultura | H19: SUBSECRETARÍA DE DESARROLLO Y PROMOCIÓN ARTÍSTICA Y CULTURAL | I19: DIRECCIÓN GENERAL DE MUSEOS, ARTES VISUALES Y EXPOSICIONES | J19: Número de Actividades realizadas | K19: 800 | L19: Artística | M19: Museos para la niñez: Proyectos Kamalio y Orquesta Ensamble Da Capo | N19: Orquesta Ensamble Da Capo está compuesta por alumnos de clases de música Amadeus Mozart, a cargo del maestro Eduardo Véjar. Con instrumentos de cuerda y percusión, son una orquesta que promueve la formación artística a través de la música en infancias y juventudes. | O19: Única | P19: 46130 | Q19: 46130 | R19: 1 | S19: Música | T19: Música tradicional | U19: Muestra artística | V19: Ninguna | W19: Presencial | X19: Espacio a Cargo de la Secretaría | Y19: 8 | AB19: FALSE | AD19: FALSE | AF19: FALSE | AH19: Sin costo | AL19: ccardonav@guanajuato.gob.mx | AM19: Juventudes: Apropiación de espacios públicos: revitalizar espacios subutilizados para actividades comunitarias y culturales, con jóvenes en su diseño y gestión. | AN19: 1 Tranquilidad | AO19: 1.2 Fortalecer prevención del delito | AP19: 1.2.2 Fortalecimiento del tejido social | AQ19: 1.2.3.4 Promover una cultura de paz desde las expresiones artísticas y culturales | AR19: Cooperación | AT19: Fomento a la creación y circulación cultural. | AU19: Impulso a redes colaborativas y plataformas de visibilidad | AV19: Celebrar esquemas de colaboración para facilitar la presencia de artistas locales en ferias, festivales y redes culturales nacionales e internacionales. | AW19: Lograr un incremento anual del 10% en la circulación de obras fuera del territorio estatal. | AX19: Presentación artística | AY19: Formación | BC19: 0 | BF19: FALSE | BL19: N/A | BM19: Sí | BP19: Abierta | BR19: =VLOOKUP(BQ19, Cat_Indicadores!B:C, 2, FALSE) -> #N/A
A20: ACT00019 | B20: SC-260615-104331 | C20: 46188.447 | D20: 92 | E20: PB3572 | F20: Gestión de programas de exposiciones, actividades formativas y académicas en los Museos de la Secretaría de Cultura y actividades extramuros | G20: Creación y participación en actividades formativas y académicas de los museos adscritos a la Secretaria de Cultura | H20: SUBSECRETARÍA DE DESARROLLO Y PROMOCIÓN ARTÍSTICA Y CULTURAL | I20: DIRECCIÓN GENERAL DE MUSEOS, ARTES VISUALES Y EXPOSICIONES | J20: Número de Actividades realizadas | K20: 800 | L20: Cultural | M20: Museos para la niñez: Magic Mind para la niñez. Meditación | N20: Meditación, yoga y aromaterapia en Terraza del Jardín de las esculturas. Imparte: Ana Gabriela Barajas Hernández de Magic Mind. | O20: Única | P20: 46131 | Q20: 46131 | R20: 1 | S20: Multidisciplinario | T20: Interdisciplinario | U20: Taller | V20: Ninguna | W20: Presencial | X20: Espacio a Cargo de la Secretaría | Y20: 8 | AB20: FALSE | AD20: FALSE | AF20: FALSE | AH20: Sin costo | AL20: ccardonav@guanajuato.gob.mx | AM20: Juventudes: Apropiación de espacios públicos: revitalizar espacios subutilizados para actividades comunitarias y culturales, con jóvenes en su diseño y gestión. | AN20: 1 Tranquilidad | AO20: 1.2 Fortalecer prevención del delito | AP20: 1.2.2 Fortalecimiento del tejido social | AQ20: 1.2.3.4 Promover una cultura de paz desde las expresiones artísticas y culturales | AR20: Cooperación | AT20: Sostenibilidad del trabajo cultural y la economía creativa. | AU20: Consolidación de los mecanismos de gobernanza para el uso de los espacios cultuales y zonas patrimoniales. | AV20: Diseñar programas de formación y gestión cultural de base comunitaria. | AW20: Incrementar un 30% la participación de grupos, colectivos y comunidades en procesos de memoria, investigación, divulgación y difusión del patrimonio material e inmaterial | AX20: Taller | AY20: Formación | BC20: 0 | BF20: FALSE | BL20: N/A | BM20: Sí | BP20: Abierta | BR20: =VLOOKUP(BQ20, Cat_Indicadores!B:C, 2, FALSE) -> #N/A
A21: ACT00020 | B21: SC-260615-112323 | C21: 46188.475 | D21: 92 | E21: PB3572 | F21: Gestión de programas de exposiciones, actividades formativas y académicas en los Museos de la Secretaría de Cultura y actividades extramuros | G21: Creación y participación en actividades formativas y académicas de los museos adscritos a la Secretaria de Cultura | H21: SUBSECRETARÍA DE DESARROLLO Y PROMOCIÓN ARTÍSTICA Y CULTURAL | I21: DIRECCIÓN GENERAL DE MUSEOS, ARTES VISUALES Y EXPOSICIONES | J21: Número de Actividades realizadas | K21: 800 | L21: Cultural | M21: Museos para la niñez: Cómo visitar un museo para niños | N21: La Plataforma de Arte emergente del Bajío LANZA te invita a participar en este divertido taller en el que podrás aprender cómo conocer y disfrutar de los museos. | O21: Única | P21: 46131 | Q21: 46131 | R21: 1 | S21: Cultura comunitaria | T21: Mediación cultural | U21: Taller | V21: Ninguna | W21: Presencial | X21: Espacio a Cargo de la Secretaría | Y21: 8 | AB21: FALSE | AD21: FALSE | AF21: FALSE | AH21: Sin costo | AL21: ccardonav@guanajuato.gob.mx | AM21: Juventudes: Apropiación de espacios públicos: revitalizar espacios subutilizados para actividades comunitarias y culturales, con jóvenes en su diseño y gestión. | AN21: 2 Igualdad | AO21: 2.4 Reducir brechas de desigualdad | AP21: 2.4.3 Descentralización de la oferta cultural | AQ21: 2.4.3.1 Impulsar el desarrollo artístico y cultural entre infancias y juventudes | AR21: Cooperación | AT21: Fortalecimiento de la participación ciudadana y la mediación cultural | AU21: Fortalecimiento del diálogo, la mediación y las capacidades de las redes comunitarias. | AV21: Diseñar e impartir talleres de formación en derechos culturales | AW21: Incrementar en 25% la oferta cultural realizada en los municipios. | AX21: Taller | AY21: Formación | BC21: 0 | BF21: FALSE | BL21: N/A | BM21: Sí | BP21: Abierta | BR21: =VLOOKUP(BQ21, Cat_Indicadores!B:C, 2, FALSE) -> #N/A
A22: ACT00021 | B22: SC-260615-113141 | C22: 46188.48 | D22: 92 | E22: PB3572 | F22: Gestión de programas de exposiciones, actividades formativas y académicas en los Museos de la Secretaría de Cultura y actividades extramuros | G22: Creación y participación en actividades formativas y académicas de los museos adscritos a la Secretaria de Cultura | H22: SUBSECRETARÍA DE DESARROLLO Y PROMOCIÓN ARTÍSTICA Y CULTURAL | I22: DIRECCIÓN GENERAL DE MUSEOS, ARTES VISUALES Y EXPOSICIONES | J22: Número de Actividades realizadas | K22: 800 | L22: Artística | M22: Museos para la niñez: Ensamble Sinfónico Oviedo | N22: Déjate sorprender por las maravillosas piezas musicales que las niñas, niños y adolescentes del Instituto Oviedo nos traerán en este mes de las infancias. Acompáñanos en este recital integrado de pequeñas piezas camerísticas y concertantes de los períodos Barroco, Clásico y Romántico; yendo desde Vivaldi y Corelli hasta Busoni. | O22: Única | P22: 46188 | Q22: 46188 | R22: 1 | S22: Música | T22: Orquestas | U22: Muestra artística | V22: Ninguna | W22: Presencial | X22: Espacio a Cargo de la Secretaría | Y22: 8 | AB22: FALSE | AD22: FALSE | AF22: FALSE | AH22: Sin costo | AL22: ccardonav@guanajuato.gob.mx | AM22: Juventudes: Apropiación de espacios públicos: revitalizar espacios subutilizados para actividades comunitarias y culturales, con jóvenes en su diseño y gestión. | AN22: 1 Tranquilidad | AO22: 1.2 Fortalecer prevención del delito | AP22: 1.2.2 Fortalecimiento del tejido social | AQ22: 1.2.3.4 Promover una cultura de paz desde las expresiones artísticas y culturales | AR22: Cooperación | AT22: Fortalecimiento de la participación ciudadana y la mediación cultural | AU22: Fortalecimiento del diálogo, la mediación y las capacidades de las redes comunitarias. | AV22: Diseñar e impartir talleres de formación en derechos culturales | AW22: Incrementar en 25% la oferta cultural realizada en los municipios. | AX22: Presentación artística | AY22: Formación | BC22: 0 | BF22: FALSE | BL22: N/A | BM22: Sí | BP22: Abierta | BR22: =VLOOKUP(BQ22, Cat_Indicadores!B:C, 2, FALSE) -> #N/A
A23: ACT00022 | B23: SC-260615-114225 | C23: 46188.488 | D23: 92 | E23: PB3572 | F23: Gestión de programas de exposiciones, actividades formativas y académicas en los Museos de la Secretaría de Cultura y actividades extramuros | G23: Creación y participación en actividades formativas y académicas de los museos adscritos a la Secretaria de Cultura | H23: SUBSECRETARÍA DE DESARROLLO Y PROMOCIÓN ARTÍSTICA Y CULTURAL | I23: DIRECCIÓN GENERAL DE MUSEOS, ARTES VISUALES Y EXPOSICIONES | J23: Número de Actividades realizadas | K23: 800 | L23: Cultural | M23: Musos para la niñez: Misión Olimpo y un poco de IA | N23: ICONMUNITY invita a participar a las niñas a que exploten su creatividad al máximo utilizando la IA para entrenar un modelo basado en imágenes y videos de la instalación ubicada en el museo. | O23: Única | P23: 46137 | Q23: 46137 | R23: 1 | S23: Artes visuales | T23: Arte digital | U23: Taller | V23: Ninguna | W23: Presencial | X23: Espacio a Cargo de la Secretaría | Y23: 8 | AB23: FALSE | AD23: FALSE | AF23: FALSE | AH23: Sin costo | AL23: ccardonav@guanajuato.gob.mx | AM23: Juventudes: Apropiación de espacios públicos: revitalizar espacios subutilizados para actividades comunitarias y culturales, con jóvenes en su diseño y gestión. | AN23: 2 Igualdad | AO23: 2.4 Reducir brechas de desigualdad | AP23: 2.4.3 Descentralización de la oferta cultural | AQ23: 2.4.3.1 Impulsar el desarrollo artístico y cultural entre infancias y juventudes | AR23: Cooperación | AT23: Fortalecimiento de la participación ciudadana y la mediación cultural | AU23: Fortalecimiento del diálogo, la mediación y las capacidades de las redes comunitarias. | AV23: Diseñar e impartir talleres de formación en derechos culturales | AW23: Incrementar en 25% la oferta cultural realizada en los municipios. | AX23: Taller | AY23: Formación | BC23: 0 | BF23: FALSE | BL23: N/A | BM23: Sí | BP23: Abierta | BR23: =VLOOKUP(BQ23, Cat_Indicadores!B:C, 2, FALSE) -> #N/A
A24: ACT00023 | B24: SC-260615-115027 | C24: 46188.493 | D24: 92 | E24: PB3572 | F24: Gestión de programas de exposiciones, actividades formativas y académicas en los Museos de la Secretaría de Cultura y actividades extramuros | G24: Creación y participación en actividades formativas y académicas de los museos adscritos a la Secretaria de Cultura | H24: SUBSECRETARÍA DE DESARROLLO Y PROMOCIÓN ARTÍSTICA Y CULTURAL | I24: DIRECCIÓN GENERAL DE MUSEOS, ARTES VISUALES Y EXPOSICIONES | J24: Número de Actividades realizadas | K24: 800 | L24: Artística | M24: Encuentro de Danza Guanajuato | N24: En el marco del Dïa de la Danza habitemos los espacios del museo desde los diferentes estilos de danza y encontramos las posibilidades de expresión a través del cuerpo con la participación de 15 academias y colectivos guanajuatenses. En colaboración con Vaivén. Cuerpos en Escena. | O24: Única | P24: 46138 | Q24: 46138 | R24: 1 | S24: Artes escénicas | T24: Danza contemporánea | U24: Presentación artística | V24: Ninguna | W24: Presencial | X24: Espacio a Cargo de la Secretaría | Y24: 8 | AB24: FALSE | AD24: FALSE | AF24: FALSE | AH24: Sin costo | AL24: ccardonav@guanajuato.gob.mx | AM24: Leer para crecer. | AN24: 2 Igualdad | AO24: 2.4 Reducir brechas de desigualdad | AP24: 2.4.3 Descentralización de la oferta cultural | AQ24: 2.4.3.1 Impulsar el desarrollo artístico y cultural entre infancias y juventudes | AR24: Cooperación | AT24: Fomento a la creación y circulación cultural. | AU24: Incentivar la creación y producción artística y cultural de agentes locales. | AV24: Diseñar e implementar un sistema de reconocimiento público a las comunidades culturales. | AW24: Incrementar nuevas producciones, obras y proyectos culturales en un 15% anual. | AX24: Taller | AY24: Formación | BC24: 0 | BF24: FALSE | BL24: N/A | BM24: Sí | BP24: Abierta | BR24: =VLOOKUP(BQ24, Cat_Indicadores!B:C, 2, FALSE) -> #N/A
A25: ACT00024 | B25: SC-260615-120517 | C25: 46188.504 | D25: 92 | E25: PB3572 | F25: Gestión de programas de exposiciones, actividades formativas y académicas en los Museos de la Secretaría de Cultura y actividades extramuros | G25: Creación y participación en actividades formativas y académicas de los museos adscritos a la Secretaria de Cultura | H25: SUBSECRETARÍA DE DESARROLLO Y PROMOCIÓN ARTÍSTICA Y CULTURAL | I25: DIRECCIÓN GENERAL DE MUSEOS, ARTES VISUALES Y EXPOSICIONES | J25: Número de Actividades realizadas | K25: 800 | L25: Artística | M25: Museos para la niñez: "Donde nacen los sueños" Ballet infantil | N25: Disfruta del poder del ballet infantil como un lenguaje universal que acompaña el desarrollo, fortalece la disciplina y celebra la imaginación. Presenta: Rallye Studio Dirección: Ana Guillermina Oropeza y Mariah José Paloma Hurtado Martínez. | O25: Única | P25: 46138 | Q25: 46138 | R25: 1 | S25: Artes escénicas | T25: Danza tradicional | U25: Presentación artística | V25: Ninguna | W25: Presencial | X25: Espacio a Cargo de la Secretaría | Y25: 8 | AB25: FALSE | AD25: FALSE | AF25: FALSE | AH25: Sin costo | AL25: ccardonav@guanajuato.gob.mx | AM25: Juventudes: Apropiación de espacios públicos: revitalizar espacios subutilizados para actividades comunitarias y culturales, con jóvenes en su diseño y gestión. | AN25: 2 Igualdad | AO25: 2.4 Reducir brechas de desigualdad | AP25: 2.4.3 Descentralización de la oferta cultural | AQ25: 2.4.3.1 Impulsar el desarrollo artístico y cultural entre infancias y juventudes | AR25: Cooperación | AT25: Fomento a la creación y circulación cultural. | AU25: Incentivar la creación y producción artística y cultural de agentes locales. | AV25: Diseñar e implementar un sistema de reconocimiento público a las comunidades culturales. | AW25: Incrementar nuevas producciones, obras y proyectos culturales en un 15% anual. | AX25: Presentación artística | AY25: Formación | BC25: 0 | BF25: FALSE | BL25: N/A | BM25: Sí | BP25: Abierta | BR25: =VLOOKUP(BQ25, Cat_Indicadores!B:C, 2, FALSE) -> #N/A
A26: ACT00025 | B26: SC-260615-122541 | C26: 46188.518 | D26: 92 | E26: PB3572 | F26: Gestión de programas de exposiciones, actividades formativas y académicas en los Museos de la Secretaría de Cultura y actividades extramuros | G26: Creación y participación en actividades formativas y académicas de los museos adscritos a la Secretaria de Cultura | H26: SUBSECRETARÍA DE DESARROLLO Y PROMOCIÓN ARTÍSTICA Y CULTURAL | I26: DIRECCIÓN GENERAL DE MUSEOS, ARTES VISUALES Y EXPOSICIONES | J26: Número de Actividades realizadas | K26: 800 | L26: Cultural | M26: Palabras Umbral, Palabrasfilo. Hilandera: Flor Bosco. | N26: Un tejido verbal hecho con fibras extraídas de diversos poetas. Hilandera: Flor Bosco. | O26: Única | P26: 46150 | Q26: 46150 | R26: 1 | S26: Literatura | T26: Fomento a la lectura | U26: Muestra artística | V26: Ninguna | W26: Presencial | X26: Espacio a Cargo de la Secretaría | Y26: 8 | AB26: FALSE | AD26: FALSE | AF26: FALSE | AH26: Sin costo | AL26: ccardonav@guanajuato.gob.mx | AM26: Leer para crecer. | AN26: 4 Vocación | AO26: 4.4 Reforzar competencias lectoras y lógico matemáticas | AP26: 4.4.2 Competencias lectoras | AQ26: 4.4.2 Fomentar el hábito lector | AR26: Cooperación | AT26: Fomento a la creación y circulación cultural. | AU26: Incentivar la creación y producción artística y cultural de agentes locales. | AV26: Diseñar e implementar un sistema de reconocimiento público a las comunidades culturales. | AW26: Incrementar nuevas producciones, obras y proyectos culturales en un 15% anual. | AX26: Presentación artística | AY26: Formación | BC26: 0 | BF26: FALSE | BL26: N/A | BM26: Sí | BP26: Abierta | BR26: =VLOOKUP(BQ26, Cat_Indicadores!B:C, 2, FALSE) -> #N/A
A27: ACT00026 | B27: SC-260615-125555 | C27: 46188.539 | D27: 92 | E27: PB3572 | F27: Gestión de programas de exposiciones, actividades formativas y académicas en los Museos de la Secretaría de Cultura y actividades extramuros | G27: Creación y participación en actividades formativas y académicas de los museos adscritos a la Secretaria de Cultura | H27: SUBSECRETARÍA DE DESARROLLO Y PROMOCIÓN ARTÍSTICA Y CULTURAL | I27: DIRECCIÓN GENERAL DE MUSEOS, ARTES VISUALES Y EXPOSICIONES | J27: Número de Actividades realizadas | K27: 800 | L27: Cultural | M27: Entre medios y a través de. Diálogos con Miguel Mesa."Habitar ése bosque. Camila Apaez y Miguel Mesa" | N27: De forma teórica y práctica se dialogarán posibilidades para la gestación y desarrollo de proyectos artísticos, considerando los cruces entre medios, ideas, tecnología y disciplinas; tomando en cuenta la importancia de las decisiones estéticas, técnicas y políticas. El punto de partida será la exposición “Habitar ese bosque” que se encuentra expuesta en la sala CoLab del Museo de Arte e Historia de Guanajuato. | O27: Única | P27: 46157 | Q27: 46157 | R27: 1 | S27: Artes visuales | T27: Escultura | U27: Taller | V27: Ninguna | W27: Presencial | X27: Espacio a Cargo de la Secretaría | Y27: 8 | AB27: FALSE | AD27: FALSE | AF27: FALSE | AH27: Sin costo | AL27: ccardonav@guanajuato.gob.mx | AM27: Formación de formadores artísticos y culturales: Cursos y talleres de capacitación artística para docentes. Encuentros entre formadores de casas de cultura. Plataforma de colaboración entre instituciones culturales. | AN27: 1 Tranquilidad | AO27: 1.2 Fortalecer prevención del delito | AP27: 1.2.2 Fortalecimiento del tejido social | AQ27: 1.2.3.4 Promover una cultura de paz desde las expresiones artísticas y culturales | AR27: Cooperación | AT27: Impulso a la educación artística y a la profesionalización del sector cultural | AU27: Impulso a programas de formación y profesionalización para agentes culturales. | AV27: Diseñar programas de formación y profesionalización modulares y flexibles. | AW27: Incrementar un 30% la oferta de formación y profesionalización para agentes culturales. | AX27: Taller | AY27: Creación | BC27: 0 | BF27: FALSE | BL27: N/A | BM27: Sí | BP27: Abierta | BR27: =VLOOKUP(BQ27, Cat_Indicadores!B:C, 2, FALSE) -> #N/A
A28: ACT00027 | B28: SC-260615-142412 | C28: 46188.6 | D28: 92 | E28: PB3572 | F28: Gestión de programas de exposiciones, actividades formativas y académicas en los Museos de la Secretaría de Cultura y actividades extramuros | G28: Creación y participación en actividades formativas y académicas de los museos adscritos a la Secretaria de Cultura | H28: SUBSECRETARÍA DE DESARROLLO Y PROMOCIÓN ARTÍSTICA Y CULTURAL | I28: DIRECCIÓN GENERAL DE MUSEOS, ARTES VISUALES Y EXPOSICIONES | J28: Número de Actividades realizadas | K28: 800 | L28: Artística | M28: Museo en Escena. Encuentro Arte Guanajuato | N28: Presentación de performance de danza y música (saxofón) en diferentes espacios del museo como parte del programa del Dia Internacional de los Museos. | O28: Única | P28: 46159 | Q28: 46159 | R28: 1 | S28: Artes escénicas | T28: Danza tradicional | U28: Muestra artística | V28: Ninguna | W28: Presencial | X28: Espacio a Cargo de la Secretaría | Y28: 8 | AB28: FALSE | AD28: FALSE | AF28: FALSE | AH28: Sin costo | AL28: ccardonav@guanajuato.gob.mx | AM28: Juventudes: Apropiación de espacios públicos: revitalizar espacios subutilizados para actividades comunitarias y culturales, con jóvenes en su diseño y gestión. | AN28: 1 Tranquilidad | AO28: 1.2 Fortalecer prevención del delito | AP28: 1.2.2 Fortalecimiento del tejido social | AQ28: 1.2.3.4 Promover una cultura de paz desde las expresiones artísticas y culturales | AR28: Cooperación | AT28: Impulso a la educación artística y a la profesionalización del sector cultural | AU28: Impulso a programas de formación y profesionalización para agentes culturales. | AV28: Diseñar programas de formación y profesionalización modulares y flexibles. | AW28: Incrementar un 30% la oferta de formación y profesionalización para agentes culturales. | AX28: Presentación artística | AY28: Formación | BC28: 0 | BF28: FALSE | BL28: N/A | BM28: Sí | BP28: Abierta | BR28: =VLOOKUP(BQ28, Cat_Indicadores!B:C, 2, FALSE) -> #N/A
A29: ACT00028 | B29: SC-260615-143235 | C29: 46188.606 | D29: 92 | E29: PB3572 | F29: Gestión de programas de exposiciones, actividades formativas y académicas en los Museos de la Secretaría de Cultura y actividades extramuros | G29: Creación y participación en actividades formativas y académicas de los museos adscritos a la Secretaria de Cultura | H29: SUBSECRETARÍA DE DESARROLLO Y PROMOCIÓN ARTÍSTICA Y CULTURAL | I29: DIRECCIÓN GENERAL DE MUSEOS, ARTES VISUALES Y EXPOSICIONES | J29: Número de Actividades realizadas | K29: 800 | L29: Cultural | M29: Libro de Zona 102. Festival FELIZ. Región III, sector 03 y Zona 102. | N29: Cultivemos un mundo mejor a partir del arte y la literatura, abramos juntos las puertas del arte y la imaginación de las infancias. Descubre el poder de un libro. Abre una puerta al aprendizaje y la imaginación para tus hijos. ¡Ven a FELIZ y cultivemos juntos el amor a la lectura | O29: Única | P29: 46163 | Q29: 46163 | R29: 1 | S29: Literatura | T29: Fomento a la lectura | U29: Feria del libro | V29: Ninguna | W29: Presencial | X29: Espacio a Cargo de la Secretaría | Y29: 8 | AB29: FALSE | AD29: FALSE | AF29: FALSE | AH29: Sin costo | AL29: ccardonav@guanajuato.gob.mx | AM29: Leer para crecer. | AN29: 4 Vocación | AO29: 4.4 Reforzar competencias lectoras y lógico matemáticas | AP29: 4.4.2 Competencias lectoras | AQ29: 4.4.2 Fomentar el hábito lector | AR29: Cooperación | AT29: Fortalecimiento de la participación ciudadana y la mediación cultural | AU29: Fortalecimiento del diálogo, la mediación y las capacidades de las redes comunitarias. | AV29: Diseñar e impartir talleres de formación en derechos culturales | AW29: Incrementar en 25% la oferta cultural realizada en los municipios. | AX29: Feria del libro | AY29: Formación | BC29: 0 | BF29: FALSE | BL29: N/A | BM29: Sí | BP29: Abierta | BR29: =VLOOKUP(BQ29, Cat_Indicadores!B:C, 2, FALSE) -> #N/A
